{
 "cells": [
  {
   "cell_type": "code",
   "execution_count": 2,
   "id": "b59dbba1",
   "metadata": {},
   "outputs": [
    {
     "name": "stdout",
     "output_type": "stream",
     "text": [
      "Epoch 1/10\n",
      "WARNING:tensorflow:Model was constructed with shape (None, 28, 28, 1) for input KerasTensor(type_spec=TensorSpec(shape=(None, 28, 28, 1), dtype=tf.float32, name='input_2'), name='input_2', description=\"created by layer 'input_2'\"), but it was called on an input with incompatible shape (28, 28, 1, 1).\n"
     ]
    },
    {
     "name": "stderr",
     "output_type": "stream",
     "text": [
      "WARNING:tensorflow:Model was constructed with shape (None, 28, 28, 1) for input KerasTensor(type_spec=TensorSpec(shape=(None, 28, 28, 1), dtype=tf.float32, name='input_2'), name='input_2', description=\"created by layer 'input_2'\"), but it was called on an input with incompatible shape (28, 28, 1, 1).\n"
     ]
    },
    {
     "ename": "ValueError",
     "evalue": "in user code:\n\n    File \"C:\\Users\\Predator\\Envs\\kn_ml\\lib\\site-packages\\keras\\engine\\training.py\", line 1021, in train_function  *\n        return step_function(self, iterator)\n    File \"C:\\Users\\Predator\\Envs\\kn_ml\\lib\\site-packages\\keras\\engine\\training.py\", line 1010, in step_function  **\n        outputs = model.distribute_strategy.run(run_step, args=(data,))\n    File \"C:\\Users\\Predator\\Envs\\kn_ml\\lib\\site-packages\\keras\\engine\\training.py\", line 1000, in run_step  **\n        outputs = model.train_step(data)\n    File \"C:\\Users\\Predator\\Envs\\kn_ml\\lib\\site-packages\\keras\\engine\\training.py\", line 859, in train_step\n        y_pred = self(x, training=True)\n    File \"C:\\Users\\Predator\\Envs\\kn_ml\\lib\\site-packages\\keras\\utils\\traceback_utils.py\", line 67, in error_handler\n        raise e.with_traceback(filtered_tb) from None\n\n    ValueError: Exception encountered when calling layer \"conv2d_1\" (type Conv2D).\n    \n    Negative dimension size caused by subtracting 3 from 1 for '{{node sequential_1/conv2d_1/Conv2D}} = Conv2D[T=DT_FLOAT, data_format=\"NHWC\", dilations=[1, 1, 1, 1], explicit_paddings=[], padding=\"VALID\", strides=[1, 1, 1, 1], use_cudnn_on_gpu=true](sequential_1/Cast, sequential_1/conv2d_1/Conv2D/ReadVariableOp)' with input shapes: [28,28,1,1], [3,3,1,32].\n    \n    Call arguments received:\n      • inputs=tf.Tensor(shape=(28, 28, 1, 1), dtype=float32)\n",
     "output_type": "error",
     "traceback": [
      "\u001b[1;31m---------------------------------------------------------------------------\u001b[0m",
      "\u001b[1;31mValueError\u001b[0m                                Traceback (most recent call last)",
      "\u001b[1;32m~\\AppData\\Local\\Temp/ipykernel_3024/1961435506.py\u001b[0m in \u001b[0;36m<module>\u001b[1;34m\u001b[0m\n\u001b[0;32m     56\u001b[0m )\n\u001b[0;32m     57\u001b[0m \u001b[1;33m\u001b[0m\u001b[0m\n\u001b[1;32m---> 58\u001b[1;33m model.fit(\n\u001b[0m\u001b[0;32m     59\u001b[0m     \u001b[0mds_train\u001b[0m\u001b[1;33m,\u001b[0m\u001b[1;33m\u001b[0m\u001b[1;33m\u001b[0m\u001b[0m\n\u001b[0;32m     60\u001b[0m     \u001b[0mepochs\u001b[0m\u001b[1;33m=\u001b[0m\u001b[1;36m10\u001b[0m\u001b[1;33m,\u001b[0m\u001b[1;33m\u001b[0m\u001b[1;33m\u001b[0m\u001b[0m\n",
      "\u001b[1;32m~\\Envs\\kn_ml\\lib\\site-packages\\keras\\utils\\traceback_utils.py\u001b[0m in \u001b[0;36merror_handler\u001b[1;34m(*args, **kwargs)\u001b[0m\n\u001b[0;32m     65\u001b[0m     \u001b[1;32mexcept\u001b[0m \u001b[0mException\u001b[0m \u001b[1;32mas\u001b[0m \u001b[0me\u001b[0m\u001b[1;33m:\u001b[0m  \u001b[1;31m# pylint: disable=broad-except\u001b[0m\u001b[1;33m\u001b[0m\u001b[1;33m\u001b[0m\u001b[0m\n\u001b[0;32m     66\u001b[0m       \u001b[0mfiltered_tb\u001b[0m \u001b[1;33m=\u001b[0m \u001b[0m_process_traceback_frames\u001b[0m\u001b[1;33m(\u001b[0m\u001b[0me\u001b[0m\u001b[1;33m.\u001b[0m\u001b[0m__traceback__\u001b[0m\u001b[1;33m)\u001b[0m\u001b[1;33m\u001b[0m\u001b[1;33m\u001b[0m\u001b[0m\n\u001b[1;32m---> 67\u001b[1;33m       \u001b[1;32mraise\u001b[0m \u001b[0me\u001b[0m\u001b[1;33m.\u001b[0m\u001b[0mwith_traceback\u001b[0m\u001b[1;33m(\u001b[0m\u001b[0mfiltered_tb\u001b[0m\u001b[1;33m)\u001b[0m \u001b[1;32mfrom\u001b[0m \u001b[1;32mNone\u001b[0m\u001b[1;33m\u001b[0m\u001b[1;33m\u001b[0m\u001b[0m\n\u001b[0m\u001b[0;32m     68\u001b[0m     \u001b[1;32mfinally\u001b[0m\u001b[1;33m:\u001b[0m\u001b[1;33m\u001b[0m\u001b[1;33m\u001b[0m\u001b[0m\n\u001b[0;32m     69\u001b[0m       \u001b[1;32mdel\u001b[0m \u001b[0mfiltered_tb\u001b[0m\u001b[1;33m\u001b[0m\u001b[1;33m\u001b[0m\u001b[0m\n",
      "\u001b[1;32m~\\Envs\\kn_ml\\lib\\site-packages\\tensorflow\\python\\framework\\func_graph.py\u001b[0m in \u001b[0;36mautograph_handler\u001b[1;34m(*args, **kwargs)\u001b[0m\n\u001b[0;32m   1145\u001b[0m           \u001b[1;32mexcept\u001b[0m \u001b[0mException\u001b[0m \u001b[1;32mas\u001b[0m \u001b[0me\u001b[0m\u001b[1;33m:\u001b[0m  \u001b[1;31m# pylint:disable=broad-except\u001b[0m\u001b[1;33m\u001b[0m\u001b[1;33m\u001b[0m\u001b[0m\n\u001b[0;32m   1146\u001b[0m             \u001b[1;32mif\u001b[0m \u001b[0mhasattr\u001b[0m\u001b[1;33m(\u001b[0m\u001b[0me\u001b[0m\u001b[1;33m,\u001b[0m \u001b[1;34m\"ag_error_metadata\"\u001b[0m\u001b[1;33m)\u001b[0m\u001b[1;33m:\u001b[0m\u001b[1;33m\u001b[0m\u001b[1;33m\u001b[0m\u001b[0m\n\u001b[1;32m-> 1147\u001b[1;33m               \u001b[1;32mraise\u001b[0m \u001b[0me\u001b[0m\u001b[1;33m.\u001b[0m\u001b[0mag_error_metadata\u001b[0m\u001b[1;33m.\u001b[0m\u001b[0mto_exception\u001b[0m\u001b[1;33m(\u001b[0m\u001b[0me\u001b[0m\u001b[1;33m)\u001b[0m\u001b[1;33m\u001b[0m\u001b[1;33m\u001b[0m\u001b[0m\n\u001b[0m\u001b[0;32m   1148\u001b[0m             \u001b[1;32melse\u001b[0m\u001b[1;33m:\u001b[0m\u001b[1;33m\u001b[0m\u001b[1;33m\u001b[0m\u001b[0m\n\u001b[0;32m   1149\u001b[0m               \u001b[1;32mraise\u001b[0m\u001b[1;33m\u001b[0m\u001b[1;33m\u001b[0m\u001b[0m\n",
      "\u001b[1;31mValueError\u001b[0m: in user code:\n\n    File \"C:\\Users\\Predator\\Envs\\kn_ml\\lib\\site-packages\\keras\\engine\\training.py\", line 1021, in train_function  *\n        return step_function(self, iterator)\n    File \"C:\\Users\\Predator\\Envs\\kn_ml\\lib\\site-packages\\keras\\engine\\training.py\", line 1010, in step_function  **\n        outputs = model.distribute_strategy.run(run_step, args=(data,))\n    File \"C:\\Users\\Predator\\Envs\\kn_ml\\lib\\site-packages\\keras\\engine\\training.py\", line 1000, in run_step  **\n        outputs = model.train_step(data)\n    File \"C:\\Users\\Predator\\Envs\\kn_ml\\lib\\site-packages\\keras\\engine\\training.py\", line 859, in train_step\n        y_pred = self(x, training=True)\n    File \"C:\\Users\\Predator\\Envs\\kn_ml\\lib\\site-packages\\keras\\utils\\traceback_utils.py\", line 67, in error_handler\n        raise e.with_traceback(filtered_tb) from None\n\n    ValueError: Exception encountered when calling layer \"conv2d_1\" (type Conv2D).\n    \n    Negative dimension size caused by subtracting 3 from 1 for '{{node sequential_1/conv2d_1/Conv2D}} = Conv2D[T=DT_FLOAT, data_format=\"NHWC\", dilations=[1, 1, 1, 1], explicit_paddings=[], padding=\"VALID\", strides=[1, 1, 1, 1], use_cudnn_on_gpu=true](sequential_1/Cast, sequential_1/conv2d_1/Conv2D/ReadVariableOp)' with input shapes: [28,28,1,1], [3,3,1,32].\n    \n    Call arguments received:\n      • inputs=tf.Tensor(shape=(28, 28, 1, 1), dtype=float32)\n"
     ]
    }
   ],
   "source": [
    "import os\n",
    "import matplotlib.pyplot\n",
    "\n",
    "import tensorflow as tf\n",
    "from tensorflow import keras\n",
    "from tensorflow.keras import layers\n",
    "import tensorflow_datasets as tfds\n",
    "\n",
    "(ds_train, ds_test), ds_info = tfds.load(\n",
    "    \"mnist\",\n",
    "    split=[\"train\", \"test\"],\n",
    "    shuffle_files=True,\n",
    "    as_supervised=True,  # will return tuple (img, label) otherwise dict\n",
    "    with_info=True,  # able to get info about dataset\n",
    ")\n",
    "\n",
    "\n",
    "def normalize_img(image, label):\n",
    "    \"\"\"Normalizes images\"\"\"\n",
    "    return tf.cast(image, tf.float32) / 255.0, label\n",
    "\n",
    "\n",
    "AUTOTUNE = tf.data.experimental.AUTOTUNE\n",
    "BATCH_SIZE = 128\n",
    "\n",
    "\n",
    "model = keras.Sequential(\n",
    "    [\n",
    "        keras.Input((28, 28, 1)),\n",
    "        layers.Conv2D(32, 3, activation=\"relu\"),\n",
    "        layers.Flatten(),\n",
    "        tf.keras.layers.Dense(10, activation=\"softmax\"),\n",
    "    ]\n",
    ")\n",
    "\n",
    "save_callback = keras.callbacks.ModelCheckpoint(\n",
    "    \"checkpoint/\", save_weights_only=True, monitor=\"train_acc\", save_best_only=False,\n",
    ")\n",
    "\n",
    "lr_scheduler = keras.callbacks.ReduceLROnPlateau(\n",
    "    monitor=\"loss\", factor=0.1, patience=3, mode=\"max\", verbose=1\n",
    ")\n",
    "\n",
    "\n",
    "class OurOwnCallback(keras.callbacks.Callback):\n",
    "    def on_epoch_end(self, epoch, logs=None):\n",
    "        if logs.get(\"accuracy\") > 1:\n",
    "            print(\"Accuracy over 70%, quitting training\")\n",
    "            self.model.stop_training = True\n",
    "\n",
    "\n",
    "model.compile(\n",
    "    optimizer=keras.optimizers.Adam(0.01),\n",
    "    loss=keras.losses.SparseCategoricalCrossentropy(),\n",
    "    metrics=[\"accuracy\"],\n",
    ")\n",
    "\n",
    "model.fit(\n",
    "    ds_train,\n",
    "    epochs=10,\n",
    "    callbacks=[save_callback, lr_scheduler, OurOwnCallback()],\n",
    "    verbose=2,\n",
    ")"
   ]
  },
  {
   "cell_type": "code",
   "execution_count": null,
   "id": "3608bd06",
   "metadata": {},
   "outputs": [],
   "source": []
  }
 ],
 "metadata": {
  "kernelspec": {
   "display_name": "Python 3 (ipykernel)",
   "language": "python",
   "name": "python3"
  },
  "language_info": {
   "codemirror_mode": {
    "name": "ipython",
    "version": 3
   },
   "file_extension": ".py",
   "mimetype": "text/x-python",
   "name": "python",
   "nbconvert_exporter": "python",
   "pygments_lexer": "ipython3",
   "version": "3.9.6"
  }
 },
 "nbformat": 4,
 "nbformat_minor": 5
}
